Workbook

Sheet Master BOL
A1: Date: 08/08/2025 | C1: MASTER BILL OF LADING | L1: Page 1 of 2
A2: SHIP FROM | I2: Master Bill of Lading Number:
A3: Name: iStar (Roman & Sunstone)
A4: Address: 34 Maple Ave.
A5: City/State/Zip: Pine Brook, NJ 07058
A6: SID# | F6: FOB:
A7: SHIP TO | I7: CARRIER NAME: | K7: =ADDRESS!I1 -> CH Robinson
A8: Name: Target/NFI Consolidation | E8: Location #:_____________ | I8: Trailer number:
A9: Address: 910 Nestle Way | I9: Seal number(s): | K9: =ADDRESS!I3 -> 10285609
A10: City/State/Zip: Breinigville, PA 18031 | I10: SCAC: | J10: =ADDRESS!I2 -> RBTW
A11: CID# | F11: FOB: | I11: Pro number: | K11: =ADDRESS!I4 -> 523953410
A12: THIRD PARTY FREIGHT CHARGES BILL TO:
A13: Name:
A14: Address:
A15: City/State/Zip: | I15: Freight Charge Terms: (freight charges are prepaid unless marked otherwise)
A16: SPECIAL INSTRUCTIONS: Target Load ID # | F16: =ADDRESS!I5 -> 59642884 | I16: Prepaid______ Collect__X___ 3rd Party______
K17: Master Bill of Lading with underlaying Bills of Lading
I18: (check box)
A19: CUSTOMER ORDER INFORMATION
A20: CUSTMER ORDER NUMBER | E20: # PKGS | F20: WEIGHT | H20: PALLET/SLIP | J20: ADDITIONAL SHIPPER INFO
H21: (CIRCLE ONE)
E22: 40 | F22: 40 | H22: Y | I22: N
E23: 38 | F23: 38 | H23: Y | I23: N
E24: 59 | F24: 59 | H24: Y | I24: N
E25: 81 | F25: 81 | H25: Y | I25: N
E26: 70 | F26: 70 | H26: Y | I26: N
E27: 62 | F27: 62 | H27: Y | I27: N
E28: 66 | F28: 66 | H28: Y | I28: N
E29: 65 | F29: 65 | H29: Y | I29: N
A30: GRAND TOTAL | E30: =SUM(E22:E29,'Supplimental Master BOL'!E5:E25) -> 1688 | F30: =SUM(F22:G29,'Supplimental Master BOL'!F5:G25) -> 1688
A31: CARRIER INFORMATION
A32: HANDLING UNIT | C32: PACKAGE | E32: WEIGHT | F32: H.M. (X) | G32: Commodity Description | L32: LTL ONLY
A33: QTY | B33: TYPE | C33: QTY | D33: TYPE | G33: Commodities requiring special or additional careor attention in handling or stowingmust be so marked and packaged as to ensure safe transportation with ordinary care. See Section 2(e) of NMFC Item 360 | L33: NMFC # | M33: CLASS
A34: 6 | B34: Pallets | C34: 1688 | D34: BX | E34: 6698 | G34: Mix Pallets - Commodity as jewelry
A42: 6 | C42: 1688 | E42: 1688 | G42: GRAND TOTAL
A43: Where the rate is dependent on value, shippers are required to state spacificly in writing the agreed or declared value of the property as follows: | I43: COD Amount: $___________________
A45: "The agreed or declared value of the property is specifically stated by shipper to be not exceeding | I45: Fee Terms: Collect: Prepaid:
A46: _____________ per_____________."
I47: Customer check acceptable:
A48: NOTE Liability Limitation for loss or damage in this shipment may be applicable. See 49 U.S.C. 14706(c)(1)(A) and (B).
...

Sheet Supplimental Master BOL
A1: Date: 08/08/2025 | C1: SUPPLEMENTAL MASTER BILL OF LADING | L1: Page 2 of 2
A2: CUSTOMER ORDER INFORMATION
A3: CUSTMER ORDER NUMBER | E3: # PKGS | F3: WEIGHT | H3: PALLET/SLIP | J3: ADDITIONAL SHIPPER INFO
H4: (CIRCLE ONE)
E5: 61 | F5: 61 | H5: Y | I5: N
E6: 83 | F6: 83 | H6: Y | I6: N
E7: 70 | F7: 70 | H7: Y | I7: N
E8: 50 | F8: 50 | H8: Y | I8: N
E9: 70 | F9: 70 | H9: Y | I9: N
E10: 69 | F10: 69 | H10: Y | I10: N
E11: 54 | F11: 54 | H11: Y | I11: N
E12: 65 | F12: 65 | H12: Y | I12: N
E13: 65 | F13: 65 | H13: Y | I13: N
E14: 70 | F14: 70 | H14: Y | I14: N
E15: 55 | F15: 55 | H15: Y | I15: N
E16: 54 | F16: 54 | H16: Y | I16: N
... E25: 16 | F25: 16 | H25: Y | I25: N
A50: GRAND TOTAL | E50: =SUM(E5:E25,'Master BOL'!E22:E29) -> 1688 | F50: =SUM(F5:F25,'Master BOL'!F22:F29) -> 1688
A51: Additional Comments

Sheet Supplemental BOL
A1: Date: | B1: 45877 | G1: BILL OF LADING | L1: Page 1 of 1
A2: SHIP FROM
A3: Name: iStar (Roman & Sunstone) | I3: Bill of Lading Number:
A4: Address: 34 Maple Ave.
A5: City/State/Zip: Pine Brook, NJ 07058
A6: SID# | F6: FOB:
A7: SHIP TO | I7: CARRIER NAME: | K7: =ADDRESS!I1 -> CH Robinson
A8: Name: | B8: TARGET DC 0578 | E8: Location #:_____________ | I8: Trailer number:
A9: Address: | B9: =VLOOKUP(B8,ADDRESS!$A$2:$E$30,2,FALSE) -> 13790 Harvey Road | I9: Seal number(s): | K9: =ADDRESS!I3 -> 10285609
A10: City/State/Zip: | C10: =CONCATENATE(VLOOKUP(B8,ADDRESS!$A$2:$E$30,3,FALSE),", ",VLOOKUP(B8,ADDRESS!$A$2:$E$30,4,FALSE)," ",VLOOKUP(B8,ADDRESS!$A$2:$E$30,5,FALSE)) -> TYLER, TX 75706 | I10: SCAC: | J10: =ADDRESS!I2 -> RBTW
A11: CID# | F11: FOB: | I11: Pro number: | K11: =ADDRESS!I4 -> 523953410
A12: THIRD PARTY FREIGHT CHARGES BILL TO:
A13: Name:
A14: Address:
A15: City/State/Zip: | I15: Freight Charge Terms: (freight charges are prepaid unless marked otherwise)
I16: Prepaid______ Collect__X___ 3rd Party______
A17: SPECIAL INSTRUCTIONS: Target Load ID # | F17: =ADDRESS!I5 -> 59642884 | K17: Master Bill of Lading with underlaying Bills of Lading
I18: (check box)
A19: CUSTOMER ORDER INFORMATION
A20: CUSTMER ORDER NUMBER | E20: # PKGS | F20: WEIGHT | H20: PALLET/SLIP | J20: ADDITIONAL SHIPPER INFO
H21: (CIRCLE ONE)
A22: =VLOOKUP(B8,'Customer Order Info'!$A$3:$D$31,2,FALSE) -> 0215-8880831-0578 | E22: =VLOOKUP(A22,'Customer Order Info'!B3:D31,2,FALSE) -> 83 | F22: =VLOOKUP(A22,'Customer Order Info'!B3:D31,3,FALSE) -> 83 | H22: Y | I22: N
H23: Y | I23: N
H24: Y | I24: N
H25: Y | I25: N
H26: Y | I26: N
H27: Y | I27: N
H28: Y | I28: N
H29: Y | I29: N
A30: GRAND TOTAL | E30: =SUM(E22:E29) -> 83 | F30: =SUM(F22:G29) -> 83
A31: CARRIER INFORMATION
A32: HANDLING UNIT | C32: PACKAGE | E32: WEIGHT | F32: H.M. (X) | G32: Commodity Description | L32: LTL ONLY
A33: QTY | B33: TYPE | C33: QTY | D33: TYPE | G33: Commodities requiring special or additional careor attention in handling or stowingmust be so marked and packaged as to ensure safe transportation with ordinary care. See Section 2(e) of NMFC Item 360 | L33: NMFC # | M33: CLASS
A34: =E30 -> 83 | B34: BX | C34: =F30 -> 83 | D34: BX | E34: =F30 -> 83 | G34: Commodity as jewelry
A42: =SUM(A34:A41) -> 83 | C42: =SUM(C34:C41) -> 83 | E42: =SUM(E34:E41) -> 83 | G42: GRAND TOTAL
A43: Where the rate is dependent on value, shippers are required to state spacificly in writing the agreed or declared value of the property as follows: | I43: COD Amount: $___________________
A45: "The agreed or declared value of the property is specifically stated by shipper to be not exceeding | I45: Fee Terms: Collect: Prepaid:
A46: _____________ per_____________."
I47: Customer check acceptable:
A48: NOTE Liability Limitation for loss or damage in this shipment may be applicable. See 49 U.S.C. 14706(c)(1)(A) and (B).
...

Sheet ADDRESS
A1: DC | B1: ADDRESS | C1: TOWN | D1: STATE | E1: ZIP | H1: CARRIER | I1: CH Robinson
A2: TARGET DC 0553 | B2: 7895 REDWOOD AVE | C2: FONTANA | D2: CA | E2: 92336 | H2: SCAC: | I2: RBTW
A3: TARGET DC 0554 | B3: 34800 UNITED AVE | C3: PUEBLO | D3: CO | E3: 81001 | H3: SEAL: | I3: 10285609
A4: TARGET DC 0560 | B4: 423 MOUNT VERNON RD | C4: STUARTS DRAFT | D4: VA | E4: 24477 | H4: PRO #: | I4: 523953410
A5: TARGET DC 0551 | B5: 7120 HWY 65 NE | C5: FRIDLEY | D5: MN | E5: 55432 | H5: TARGET Load: | I5: 59642884
A6: TARGET DC 0555 | B6: 2050 E BEAMER ST | C6: WOODLAND | D6: CA | E6: 95776
A7: TARGET DC 0556 | B7: 110 W JORDAN RD | C7: TIFTON | D7: GA | E7: 31793
A8: TARGET DC 0557 | B8: 1100 E VALLEY RD | C8: OCONOMOWOC | D8: WI | E8: 53066
A9: TARGET DC 0558 | B9: 875 BETA DRIVE SW | C9: ALBANY | D9: OR | E9: 97321
A10: TARGET DC 0559 | B10: 1350 S GIRLS SCHOOL RD | C10: INDIANAPOLIS | D10: IN | E10: 46231
A11: TARGET DC 0578 | B11: 13790 Harvey Road | C11: TYLER | D11: TX | E11: 75706
A12: TARGET DC 0579 | B12: 131 NORTH RD | C12: WILTON | D12: NY | E12: 12831
A13: TARGET DC 0580 | B13: 6305 GREENBRIER RD | C13: MADISON | D13: AL | E13: 35756
A14: TARGET DC 0587 | B14: 12905 East L Avenue | C14: GALESBURG | D14: MI | E14: 49053
A15: TARGET DC 0588 | B15: 7101 W VAN BUREN | C15: PHOENIX | D15: AZ | E15: 85043
A16: TARGET DC 0589 | B16: 3325 ARCHER DR | C16: CHAMBERSBURG | D16: PA | E16: 17202
A17: TARGET DC 0590 | B17: 6601 HUDSON RD | C17: CEDAR FALLS | D17: IA | E17: 50613
... A25: TARGET DC 3808 | B25: 895 SUNBURY RD | C25: MIDWAY | D25: GA | E25: 31320
A26: TARGET DC 3811 | B26: 1900 Stover Court | C26: NEWTON | D26: NC | E26: 28658-8983
A27: TARGET DC 3856 | B27: 23000 Van Buren Boulevard | C27: Riverside | D27: CA | E27: 92518
A28: TARGET DC 3857 | B28: 300 CREEKVIEW AVE, BLDG H | C28: LOGAN TWP | D28: NJ | E28: 08085
A29: TARGET DC 3865 | B29: 3501 S Pulaski Rd | C29: Chicago | D29: IL | E29: 60623
A30: TARGET DC 3868 | B30: 1050 Site Pkwy | C30: Hampton | D30: GA | E30: 30228

Sheet Customer Order Info
B2: Row Labels | C2: Count of Carton Number | D2: Sum of Gross Weight
A3: TARGET DC 0551 | B3: 0215-8880831-0551 | C3: 40 | D3: 40
A4: TARGET DC 0553 | B4: 0215-8880831-0553 | C4: 38 | D4: 38
A5: TARGET DC 0554 | B5: 0215-8880831-0554 | C5: 59 | D5: 59
A6: TARGET DC 0555 | B6: 0215-8880831-0555 | C6: 81 | D6: 81
A7: TARGET DC 0556 | B7: 0215-8880831-0556 | C7: 70 | D7: 70
A8: TARGET DC 0557 | B8: 0215-8880831-0557 | C8: 62 | D8: 62
A9: TARGET DC 0558 | B9: 0215-8880831-0558 | C9: 66 | D9: 66
A10: TARGET DC 0559 | B10: 0215-8880831-0559 | C10: 65 | D10: 65
A11: TARGET DC 0560 | B11: 0215-8880831-0560 | C11: 61 | D11: 61
A12: TARGET DC 0578 | B12: 0215-8880831-0578 | C12: 83 | D12: 83
A13: TARGET DC 0579 | B13: 0215-8880831-0579 | C13: 70 | D13: 70
A14: TARGET DC 0580 | B14: 0215-8880831-0580 | C14: 50 | D14: 50
... A31: TARGET DC 3868 | B31: 0215-8880831-3868 | C31: 16 | D31: 16
B32: GRAND TOTAL | C32: =SUM(C3:C31) -> 1688 | D32: =SUM(D3:D31) -> 1688
